<?xml version="1.0" ?>
<sdf version="1.6">
  <model name="quadcopter_with_camera">

    <!-- ROS 2 control plugin -->
    <plugin name="gazebo_ros2_control" filename="libgazebo_ros2_control.so">
      <ros>
        <namespace>/quadcopter_with_camera</namespace>
        <remapping>cmd_vel:=/quadcopter_with_camera/cmd_vel</remapping>
      </ros>
      <robotNamespace>/quadcopter_with_camera</robotNamespace>
      <controlConfigFile>$(find quadcopter_description)/config/control.yaml</controlConfigFile>
    </plugin>

    <link name="base_link">
      <!-- Inertial properties -->
      <inertial>
        <mass>1.0</mass>
        <inertia>
          <ixx>0.05</ixx>
          <iyy>0.05</iyy>
          <izz>0.05</izz>
        </inertia>
      </inertial>

      <!-- Visual representation of the quadcopter -->
      <visual name="quadcopter_visual">
        <geometry>
          <box>
            <size>0.5 0.5 0.1</size>
          </box>
        </geometry>
        <material>
          <ambient>0.0 1.0 0.0 1.0</ambient>
          <diffuse>0.0 1.0 0.0 1.0</diffuse>
        </material>
      </visual>

      <!-- Collision properties of the quadcopter -->
      <collision name="quadcopter_collision">
        <geometry>
          <box>
            <size>0.5 0.5 0.1</size>
          </box>
        </geometry>
        <surface>
          <contact>
            <collide_without_contact>false</collide_without_contact>
            <collide_bitmask>1</collide_bitmask>
            <ode/>
          </contact>
          <bounce/>
          <friction>
            <ode/>
          </friction>
        </surface>
      </collision>

      <!-- Camera sensor attached to the quadcopter -->
      <sensor name="camera_sensor" type="camera">
        <pose>0 0 0.2 0 0 0</pose>
        <camera>
          <horizontal_fov>1.047</horizontal_fov>
          <image>
            <width>640</width>
            <height>480</height>
            <format>R8G8B8</format>
          </image>
          <clip>
            <near>0.1</near>
            <far>100</far>
          </clip>
        </camera>
        <always_on>true</always_on>
        <update_rate>30</update_rate>
        <plugin name="camera_controller" filename="libgazebo_ros_camera.so">
          <ros>
            <namespace>/quadcopter_with_camera</namespace>
            <remapping>image_raw:=/drone/camera/image_raw</remapping> <!-- Remap the topic for the image feed -->
          </ros>
          <cameraName>camera_sensor</cameraName>
          <frameName>camera_link</frameName>
        </plugin>
      </sensor>
    </link>

        <!-- Joint to control up and down movement -->
    <joint name="base_link_joint" type="prismatic">
      <parent>world</parent>
      <child>base_link</child>
      <axis>
        <xyz>0 0 1</xyz> <!-- Z-axis for up/down movement -->
        <limit>
          <lower>-5.0</lower>  <!-- Allow up to 5 meters down -->
          <upper>5.0</upper>   <!-- Allow up to 5 meters up -->
        </limit>
      </axis>
    </joint>
  </model>
</sdf>